Workbook

Sheet Flujos
A1: ID_distribuidor | B1: Distribuidor | C1: País
A2: 1 | B2: TDB | C2: Brasil
A3: 2 | B3: TCL | C3: Chile
A4: 3 | B4: Toyotoshi | C4: Paraguay
A5: 4 | B5: Ayax | C5: Uruguay
A6: 5 | B6: Toyosa | C6: Bolivia

Sheet Modelos
A1: Modelos
A2: Hilux
A3: Fortuner
A4: Corolla Cross
A5: Corolla
A6: Yaris
A7: Hiace
A8: GR86

Sheet Parte
A1: Parte del vehículo
A2: Paragolpe delantero
A3: Paragolpe trasero
A4: Guardabarro delantero derecho
A5: Guardabarro delantero izquierdo
A6: Guardabarro trasero derecho
A7: Guardabarro trasero izquierdo
A8: Capot
A9: Parrilla
A10: Espejo exterior derecho
A11: Espejo exterior izquierdo
A12: Parabrisas delantero
... A31: Interior caja pick-up (Hilux)

Sheet Tipo daño
A1: Tipo de daño
A2: Rayado
A3: Abollado
A4: Mellado
A5: Filo de panel
A6: Fallo de pintura
A7: Roto
A8: Doblado
A9: Faltante
A10: Desprendido
A11: Cortado

Sheet Unidades
A1: ID_VIN | B1: Equipo | C1: Flujo | D1: País | E1: Modelo | F1: Secuencia | G1: Fecha de carga
A2: 8AJAKH1Z6CPAHTAGY | B2: 4774 | C2: TDB | D2: Brasil | E2: Corolla | F2: 4 | G2: 2025-01-16
A3: 8AJK52FPKH2DNMMJB | B3: 4219 | C3: Toyosa | D3: Bolivia | E3: Yaris | F3: 2 | G3: 2024-12-11
A4: 8AJV4X5W0BHKCHDKX | B4: 3553 | C4: TDB | D4: Brasil | E4: Fortuner | F4: 6 | G4: 2024-11-29
A5: 8AJZ0ZCXUJSJ7ZHL2 | B5: 1333 | C5: TCL | D5: Chile | E5: Fortuner | F5: 1 | G5: 2024-11-09
A6: 8AJJG85LYP7SJJVJW | B6: 5107 | C6: Ayax | D6: Uruguay | E6: Corolla | F6: 6 | G6: 2024-09-21
A7: 8AJTDBDX3PCN9U95A | B7: 1777 | C7: TCL | D7: Chile | E7: Hiace | F7: 5 | G7: 2024-11-22
A8: 8AJKFA0092TDX4TGN | B8: 2110 | C8: TDB | D8: Brasil | E8: Yaris | F8: 1 | G8: 2024-11-13
A9: 8AJA754LB58CTC22E | B9: 4330 | C9: Ayax | D9: Uruguay | E9: Yaris | F9: 3 | G9: 2024-10-14
A10: 8AJ5PGU1GL9YRUDHM | B10: 5107 | C10: Toyosa | D10: Bolivia | E10: Yaris | F10: 4 | G10: 2024-09-21
A11: 8AJCXH65CHZHE7VS2 | B11: 3886 | C11: TDB | D11: Brasil | E11: Fortuner | F11: 2 | G11: 2024-07-20
A12: 8AJMP5BYYC13DGUEG | B12: 4219 | C12: Ayax | D12: Uruguay | E12: Fortuner | F12: 2 | G12: 2025-01-13
A13: 8AJDYUAD1HPS56FAN | B13: 4219 | C13: Toyosa | D13: Bolivia | E13: Corolla Cross | F13: 7 | G13: 2025-03-12
... A201: 8AJ4VL1VHG0Z7E09F | B201: 4774 | C201: Toyotoshi | D201: Paraguay | E201: Hiace | F201: 6 | G201: 2024-07-30

Sheet Inspecciones
A1: ID_Inspección | B1: ID_VIN | C1: Fecha de inspección | D1: Parte del vehículo | E1: Tipo de daño | F1: Cuadrante | G1: Comentario | H1: Foto del daño (ruta) | I1: Firma inspector (ruta)
A2: 89fbae8e | B2: 8AJAKH1Z6CPAHTAGY | C2: 2025-01-16 | D2: Optica trasera derecha | E2: Rayado | F2: 8 | H2: images/89fbae8e_foto.jpg | I2: images/89fbae8e_firma.png
A3: 02a3c244 | B3: 8AJAKH1Z6CPAHTAGY | C3: 2025-01-16 | D3: Pilar delantero izquierdo | E3: Rayado | F3: 4 | H3: images/02a3c244_foto.jpg | I3: images/02a3c244_firma.png
A4: 0d1dbdb8 | B4: 8AJK52FPKH2DNMMJB | C4: 2024-12-11 | D4: Parrilla | E4: Desprendido | F4: 4 | G4: Requiere seguimiento | H4: images/0d1dbdb8_foto.jpg | I4: images/0d1dbdb8_firma.png
A5: ae6ff580 | B5: 8AJK52FPKH2DNMMJB | C5: 2024-12-11 | D5: Espejo exterior derecho | E5: Filo de panel | F5: 9 | G5: Revisar | H5: images/ae6ff580_foto.jpg | I5: images/ae6ff580_firma.png
A6: ebac89cf | B6: 8AJV4X5W0BHKCHDKX | C6: 2024-11-29 | D6: Espejo exterior izquierdo | E6: Faltante | F6: 2 | G6: Requiere seguimiento | H6: images/ebac89cf_foto.jpg | I6: images/ebac89cf_firma.png
A7: 1fb10442 | B7: 8AJV4X5W0BHKCHDKX | C7: 2024-11-29 | D7: Pilar trasero derecho | E7: Fallo de pintura | F7: 0 | H7: images/1fb10442_foto.jpg | I7: images/1fb10442_firma.png
A8: e0e9cad4 | B8: 8AJZ0ZCXUJSJ7ZHL2 | C8: 2024-11-09 | D8: Pilar delantero derecho | E8: Cortado | F8: 8 | H8: images/e0e9cad4_foto.jpg | I8: images/e0e9cad4_firma.png
A9: 8f8c2865 | B9: 8AJTDBDX3PCN9U95A | C9: 2024-11-22 | D9: Pilar trasero izquierdo | E9: Filo de panel | F9: 5 | H9: images/8f8c2865_foto.jpg | I9: images/8f8c2865_firma.png
A10: 53c8fdf0 | B10: 8AJTDBDX3PCN9U95A | C10: 2024-11-22 | D10: Puerta trasera derecha | E10: Roto | F10: 7 | H10: images/53c8fdf0_foto.jpg | I10: images/53c8fdf0_firma.png
A11: 99fa5ef6 | B11: 8AJKFA0092TDX4TGN | C11: 2024-11-13 | D11: Estribo lateral izquierdo | E11: Fallo de pintura | F11: 0 | G11: Leve | H11: images/99fa5ef6_foto.jpg | I11: images/99fa5ef6_firma.png
A12: d5c70e38 | B12: 8AJKFA0092TDX4TGN | C12: 2024-11-13 | D12: Guardabarro delantero izquierdo | E12: Mellado | F12: 8 | G12: Leve | H12: images/d5c70e38_foto.jpg | I12: images/d5c70e38_firma.png
A13: 01acd618 | B13: 8AJKFA0092TDX4TGN | C13: 2024-11-13 | D13: Puerta trasera izquierda | E13: Doblado | F13: 1 | G13: Requiere seguimiento | H13: images/01acd618_foto.jpg | I13: images/01acd618_firma.png
A14: 0b01241d | B14: 8AJA754LB58CTC22E | C14: 2024-10-14 | D14: Interior caja pick-up (Hilux) | E14: Fallo de pintura | F14: 6 | G14: Revisar | H14: images/0b01241d_foto.jpg | I14: images/0b01241d_firma.png
A15: 765610b1 | B15: 8AJA754LB58CTC22E | C15: 2024-10-14 | D15: Zócalo lateral derecho | E15: Cortado | F15: 0 | G15: Requiere seguimiento | H15: images/765610b1_foto.jpg | I15: images/765610b1_firma.png
A16: 584a94e6 | B16: 8AJ5PGU1GL9YRUDHM | C16: 2024-09-21 | D16: Pilar delantero izquierdo | E16: Rayado | F16: 7 | H16: images/584a94e6_foto.jpg | I16: images/584a94e6_firma.png
A17: 826c8f2a | B17: 8AJ5PGU1GL9YRUDHM | C17: 2024-09-21 | D17: Interior caja pick-up (Hilux) | E17: Roto | F17: 0 | G17: Leve | H17: images/826c8f2a_foto.jpg | I17: images/826c8f2a_firma.png
A18: 2096813b | B18: 8AJCXH65CHZHE7VS2 | C18: 2024-07-20 | D18: Zócalo lateral derecho | E18: Roto | F18: 3 | G18: Revisar | H18: images/2096813b_foto.jpg | I18: images/2096813b_firma.png
A19: ed22941a | B19: 8AJCXH65CHZHE7VS2 | C19: 2024-07-20 | D19: Llantas | E19: Rayado | F19: 8 | G19: Revisar | H19: images/ed22941a_foto.jpg | I19: images/ed22941a_firma.png
A20: a1a439f5 | B20: 8AJCXH65CHZHE7VS2 | C20: 2024-07-20 | D20: Puerta trasera derecha | E20: Filo de panel | F20: 1 | H20: images/a1a439f5_foto.jpg | I20: images/a1a439f5_firma.png
A21: e5794995 | B21: 8AJMP5BYYC13DGUEG | C21: 2025-01-13 | D21: Parabrisas delantero | E21: Doblado | F21: 2 | H21: images/e5794995_foto.jpg | I21: images/e5794995_firma.png
A22: cba45a57 | B22: 8AJDYUAD1HPS56FAN | C22: 2025-03-12 | D22: Optica trasera izquierda | E22: Roto | F22: 4 | G22: Revisar | H22: images/cba45a57_foto.jpg | I22: images/cba45a57_firma.png
A23: 29dd284e | B23: 8AJFK8WU1BWT5F8CG | C23: 2024-12-24 | D23: Guardabarro delantero derecho | E23: Abollado | F23: 0 | G23: Leve | H23: images/29dd284e_foto.jpg | I23: images/29dd284e_firma.png
A24: d9c304e8 | B24: 8AJ8VWBCYVLJZLJEY | C24: 2024-06-05 | D24: Puerta delantera izquierda | E24: Mellado | F24: 5 | G24: Revisar | H24: images/d9c304e8_foto.jpg | I24: images/d9c304e8_firma.png
A25: b47868ad | B25: 8AJJ61FKGMZ5TJ6BX | C25: 2024-11-18 | D25: Pilar delantero derecho | E25: Cortado | F25: 2 | G25: Leve | H25: images/b47868ad_foto.jpg | I25: images/b47868ad_firma.png
A26: 2299d2bf | B26: 8AJJ61FKGMZ5TJ6BX | C26: 2024-11-18 | D26: Paragolpe trasero | E26: Filo de panel | F26: 7 | H26: images/2299d2bf_foto.jpg | I26: images/2299d2bf_firma.png
A27: 03e5770f | B27: 8AJZZMV5917HF3FPF | C27: 2024-10-06 | D27: Parabrisas delantero | E27: Abollado | F27: 8 | G27: Requiere seguimiento | H27: images/03e5770f_foto.jpg | I27: images/03e5770f_firma.png
A28: d482a5ad | B28: 8AJF0NBSG7M45HYPK | C28: 2024-11-27 | D28: Estribo lateral derecho | E28: Fallo de pintura | F28: 6 | H28: images/d482a5ad_foto.jpg | I28: images/d482a5ad_firma.png
A29: 85d77982 | B29: 8AJF0NBSG7M45HYPK | C29: 2024-11-27 | D29: Guardabarro trasero izquierdo | E29: Filo de panel | F29: 1 | G29: Leve | H29: images/85d77982_foto.jpg | I29: images/85d77982_firma.png
A30: 325b13cb | B30: 8AJP9U7D9F8JDR1LX | C30: 2025-03-23 | D30: Techo | E30: Faltante | F30: 7 | H30: images/325b13cb_foto.jpg | I30: images/325b13cb_firma.png
A31: a632928e | B31: 8AJJ0A7U01ZNCYLL4 | C31: 2024-12-27 | D31: Guardabarro trasero derecho | E31: Rayado | F31: 2 | H31: images/a632928e_foto.jpg | I31: images/a632928e_firma.png
A32: 86faebdf | B32: 8AJPKEP8Z6XKVAKRW | C32: 2025-01-13 | D32: Capot | E32: Faltante | F32: 9 | G32: Revisar | H32: images/86faebdf_foto.jpg | I32: images/86faebdf_firma.png
A33: d2d9cd2a | B33: 8AJPKEP8Z6XKVAKRW | C33: 2025-01-13 | D33: Espejo exterior derecho | E33: Mellado | F33: 5 | G33: Revisar | H33: images/d2d9cd2a_foto.jpg | I33: images/d2d9cd2a_firma.png
A34: 916208ea | B34: 8AJPKEP8Z6XKVAKRW | C34: 2025-01-13 | D34: Pilar delantero izquierdo | E34: Mellado | F34: 9 | H34: images/916208ea_foto.jpg | I34: images/916208ea_firma.png
A35: 9e8c1ae8 | B35: 8AJPXGZTJYA12DRF8 | C35: 2025-03-13 | D35: Paragolpe delantero | E35: Doblado | F35: 8 | G35: Revisar | H35: images/9e8c1ae8_foto.jpg | I35: images/9e8c1ae8_firma.png
A36: 5083cc69 | B36: 8AJPXGZTJYA12DRF8 | C36: 2025-03-13 | D36: Zócalo lateral derecho | E36: Cortado | F36: 1 | G36: Revisar | H36: images/5083cc69_foto.jpg | I36: images/5083cc69_firma.png
A37: 273d4e63 | B37: 8AJPXGZTJYA12DRF8 | C37: 2025-03-13 | D37: Puerta trasera izquierda | E37: Rayado | F37: 9 | G37: Leve | H37: images/273d4e63_foto.jpg | I37: images/273d4e63_firma.png
A38: b552a4d6 | B38: 8AJPUPGP6WZ52NAM1 | C38: 2025-02-05 | D38: Optica delantera derecha | E38: Cortado | F38: 4 | G38: Requiere seguimiento | H38: images/b552a4d6_foto.jpg | I38: images/b552a4d6_firma.png
A39: 6388287f | B39: 8AJPUPGP6WZ52NAM1 | C39: 2025-02-05 | D39: Llantas | E39: Roto | F39: 6 | G39: Requiere seguimiento | H39: images/6388287f_foto.jpg | I39: images/6388287f_firma.png
A40: 13cf18cc | B40: 8AJJLSM6K8P4S1B8H | C40: 2024-06-16 | D40: Puerta delantera derecha | E40: Rayado | F40: 2 | G40: Revisar | H40: images/13cf18cc_foto.jpg | I40: images/13cf18cc_firma.png
...

Sheet Listado total Precarga
A1: ID_Inspección | B1: ID_VIN | C1: Modelo | D1: Secuencia | E1: Fecha de carga | F1: Equipo | G1: Destino | H1: Parte del vehículo | I1: Tipo de daño | J1: Cuadrante | K1: Comentario
A2: =Inspecciones!A2 | B2: =Inspecciones!B2 | C2: =IFERROR(VLOOKUP(B2,Unidades!A:G,5,FALSE),"") | D2: =IFERROR(VLOOKUP(B2,Unidades!A:G,6,FALSE),"") | E2: =IFERROR(VLOOKUP(B2,Unidades!A:G,7,FALSE),"") | F2: =IFERROR(VLOOKUP(B2,Unidades!A:G,2,FALSE),"") | G2: =IFERROR(VLOOKUP(B2,Unidades!A:G,4,FALSE),"") | H2: =Inspecciones!D2 | I2: =Inspecciones!E2 | J2: =Inspecciones!F2 | K2: =Inspecciones!G2
A3: =Inspecciones!A3 | B3: =Inspecciones!B3 | C3: =IFERROR(VLOOKUP(B3,Unidades!A:G,5,FALSE),"") | D3: =IFERROR(VLOOKUP(B3,Unidades!A:G,6,FALSE),"") | E3: =IFERROR(VLOOKUP(B3,Unidades!A:G,7,FALSE),"") | F3: =IFERROR(VLOOKUP(B3,Unidades!A:G,2,FALSE),"") | G3: =IFERROR(VLOOKUP(B3,Unidades!A:G,4,FALSE),"") | H3: =Inspecciones!D3 | I3: =Inspecciones!E3 | J3: =Inspecciones!F3 | K3: =Inspecciones!G3
A4: =Inspecciones!A4 | B4: =Inspecciones!B4 | C4: =IFERROR(VLOOKUP(B4,Unidades!A:G,5,FALSE),"") | D4: =IFERROR(VLOOKUP(B4,Unidades!A:G,6,FALSE),"") | E4: =IFERROR(VLOOKUP(B4,Unidades!A:G,7,FALSE),"") | F4: =IFERROR(VLOOKUP(B4,Unidades!A:G,2,FALSE),"") | G4: =IFERROR(VLOOKUP(B4,Unidades!A:G,4,FALSE),"") | H4: =Inspecciones!D4 | I4: =Inspecciones!E4 | J4: =Inspecciones!F4 | K4: =Inspecciones!G4
A5: =Inspecciones!A5 | B5: =Inspecciones!B5 | C5: =IFERROR(VLOOKUP(B5,Unidades!A:G,5,FALSE),"") | D5: =IFERROR(VLOOKUP(B5,Unidades!A:G,6,FALSE),"") | E5: =IFERROR(VLOOKUP(B5,Unidades!A:G,7,FALSE),"") | F5: =IFERROR(VLOOKUP(B5,Unidades!A:G,2,FALSE),"") | G5: =IFERROR(VLOOKUP(B5,Unidades!A:G,4,FALSE),"") | H5: =Inspecciones!D5 | I5: =Inspecciones!E5 | J5: =Inspecciones!F5 | K5: =Inspecciones!G5
A6: =Inspecciones!A6 | B6: =Inspecciones!B6 | C6: =IFERROR(VLOOKUP(B6,Unidades!A:G,5,FALSE),"") | D6: =IFERROR(VLOOKUP(B6,Unidades!A:G,6,FALSE),"") | E6: =IFERROR(VLOOKUP(B6,Unidades!A:G,7,FALSE),"") | F6: =IFERROR(VLOOKUP(B6,Unidades!A:G,2,FALSE),"") | G6: =IFERROR(VLOOKUP(B6,Unidades!A:G,4,FALSE),"") | H6: =Inspecciones!D6 | I6: =Inspecciones!E6 | J6: =Inspecciones!F6 | K6: =Inspecciones!G6
A7: =Inspecciones!A7 | B7: =Inspecciones!B7 | C7: =IFERROR(VLOOKUP(B7,Unidades!A:G,5,FALSE),"") | D7: =IFERROR(VLOOKUP(B7,Unidades!A:G,6,FALSE),"") | E7: =IFERROR(VLOOKUP(B7,Unidades!A:G,7,FALSE),"") | F7: =IFERROR(VLOOKUP(B7,Unidades!A:G,2,FALSE),"") | G7: =IFERROR(VLOOKUP(B7,Unidades!A:G,4,FALSE),"") | H7: =Inspecciones!D7 | I7: =Inspecciones!E7 | J7: =Inspecciones!F7 | K7: =Inspecciones!G7
A8: =Inspecciones!A8 | B8: =Inspecciones!B8 | C8: =IFERROR(VLOOKUP(B8,Unidades!A:G,5,FALSE),"") | D8: =IFERROR(VLOOKUP(B8,Unidades!A:G,6,FALSE),"") | E8: =IFERROR(VLOOKUP(B8,Unidades!A:G,7,FALSE),"") | F8: =IFERROR(VLOOKUP(B8,Unidades!A:G,2,FALSE),"") | G8: =IFERROR(VLOOKUP(B8,Unidades!A:G,4,FALSE),"") | H8: =Inspecciones!D8 | I8: =Inspecciones!E8 | J8: =Inspecciones!F8 | K8: =Inspecciones!G8
A9: =Inspecciones!A9 | B9: =Inspecciones!B9 | C9: =IFERROR(VLOOKUP(B9,Unidades!A:G,5,FALSE),"") | D9: =IFERROR(VLOOKUP(B9,Unidades!A:G,6,FALSE),"") | E9: =IFERROR(VLOOKUP(B9,Unidades!A:G,7,FALSE),"") | F9: =IFERROR(VLOOKUP(B9,Unidades!A:G,2,FALSE),"") | G9: =IFERROR(VLOOKUP(B9,Unidades!A:G,4,FALSE),"") | H9: =Inspecciones!D9 | I9: =Inspecciones!E9 | J9: =Inspecciones!F9 | K9: =Inspecciones!G9
A10: =Inspecciones!A10 | B10: =Inspecciones!B10 | C10: =IFERROR(VLOOKUP(B10,Unidades!A:G,5,FALSE),"") | D10: =IFERROR(VLOOKUP(B10,Unidades!A:G,6,FALSE),"") | E10: =IFERROR(VLOOKUP(B10,Unidades!A:G,7,FALSE),"") | F10: =IFERROR(VLOOKUP(B10,Unidades!A:G,2,FALSE),"") | G10: =IFERROR(VLOOKUP(B10,Unidades!A:G,4,FALSE),"") | H10: =Inspecciones!D10 | I10: =Inspecciones!E10 | J10: =Inspecciones!F10 | K10: =Inspecciones!G10
A11: =Inspecciones!A11 | B11: =Inspecciones!B11 | C11: =IFERROR(VLOOKUP(B11,Unidades!A:G,5,FALSE),"") | D11: =IFERROR(VLOOKUP(B11,Unidades!A:G,6,FALSE),"") | E11: =IFERROR(VLOOKUP(B11,Unidades!A:G,7,FALSE),"") | F11: =IFERROR(VLOOKUP(B11,Unidades!A:G,2,FALSE),"") | G11: =IFERROR(VLOOKUP(B11,Unidades!A:G,4,FALSE),"") | H11: =Inspecciones!D11 | I11: =Inspecciones!E11 | J11: =Inspecciones!F11 | K11: =Inspecciones!G11
A12: =Inspecciones!A12 | B12: =Inspecciones!B12 | C12: =IFERROR(VLOOKUP(B12,Unidades!A:G,5,FALSE),"") | D12: =IFERROR(VLOOKUP(B12,Unidades!A:G,6,FALSE),"") | E12: =IFERROR(VLOOKUP(B12,Unidades!A:G,7,FALSE),"") | F12: =IFERROR(VLOOKUP(B12,Unidades!A:G,2,FALSE),"") | G12: =IFERROR(VLOOKUP(B12,Unidades!A:G,4,FALSE),"") | H12: =Inspecciones!D12 | I12: =Inspecciones!E12 | J12: =Inspecciones!F12 | K12: =Inspecciones!G12
A13: =Inspecciones!A13 | B13: =Inspecciones!B13 | C13: =IFERROR(VLOOKUP(B13,Unidades!A:G,5,FALSE),"") | D13: =IFERROR(VLOOKUP(B13,Unidades!A:G,6,FALSE),"") | E13: =IFERROR(VLOOKUP(B13,Unidades!A:G,7,FALSE),"") | F13: =IFERROR(VLOOKUP(B13,Unidades!A:G,2,FALSE),"") | G13: =IFERROR(VLOOKUP(B13,Unidades!A:G,4,FALSE),"") | H13: =Inspecciones!D13 | I13: =Inspecciones!E13 | J13: =Inspecciones!F13 | K13: =Inspecciones!G13
... A244: =Inspecciones!A244 | B244: =Inspecciones!B244 | C244: =IFERROR(VLOOKUP(B244,Unidades!A:G,5,FALSE),"") | D244: =IFERROR(VLOOKUP(B244,Unidades!A:G,6,FALSE),"") | E244: =IFERROR(VLOOKUP(B244,Unidades!A:G,7,FALSE),"") | F244: =IFERROR(VLOOKUP(B244,Unidades!A:G,2,FALSE),"") | G244: =IFERROR(VLOOKUP(B244,Unidades!A:G,4,FALSE),"") | H244: =Inspecciones!D244 | I244: =Inspecciones!E244 | J244: =Inspecciones!F244 | K244: =Inspecciones!G244

Sheet Resumen por parte
A1: Parte del vehículo | B1: Cantidad de daños | C1: % del total | E1: Tipo de daño | F1: Cantidad
A2: Paragolpe delantero | B2: 14 | C2: =B2/SUM($B$2:$B$31) | E2: Fallo de pintura | F2: 28
A3: Espejo exterior derecho | B3: 13 | C3: =B3/SUM($B$2:$B$32) | E3: Filo de panel | F3: 27
A4: Guardabarro delantero derecho | B4: 12 | C4: =B4/SUM($B$2:$B$33) | E4: Cortado | F4: 27
A5: Parabrisas delantero | B5: 11 | C5: =B5/SUM($B$2:$B$34) | E5: Roto | F5: 26
A6: Guardabarro delantero izquierdo | B6: 10 | C6: =B6/SUM($B$2:$B$35) | E6: Abollado | F6: 25
A7: Zócalo lateral derecho | B7: 10 | C7: =B7/SUM($B$2:$B$36) | E7: Mellado | F7: 24
A8: Optica trasera izquierda | B8: 10 | C8: =B8/SUM($B$2:$B$37) | E8: Rayado | F8: 23
A9: Guardabarro trasero derecho | B9: 10 | C9: =B9/SUM($B$2:$B$38) | E9: Faltante | F9: 22
A10: Puerta delantera derecha | B10: 10 | C10: =B10/SUM($B$2:$B$39) | E10: Doblado | F10: 22
A11: Puerta trasera derecha | B11: 9 | C11: =B11/SUM($B$2:$B$40) | E11: Desprendido | F11: 19
A12: Puerta trasera izquierda | B12: 9 | C12: =B12/SUM($B$2:$B$41)
A13: Puerta delantera izquierda | B13: 9 | C13: =B13/SUM($B$2:$B$42)
A14: Paragolpe trasero | B14: 9 | C14: =B14/SUM($B$2:$B$43)
A15: Techo | B15: 9 | C15: =B15/SUM($B$2:$B$44)
A16: Capot | B16: 9 | C16: =B16/SUM($B$2:$B$45)
A17: Pilar delantero izquierdo | B17: 8 | C17: =B17/SUM($B$2:$B$46)
A18: Llantas | B18: 8 | C18: =B18/SUM($B$2:$B$47)
A19: Estribo lateral derecho | B19: 8 | C19: =B19/SUM($B$2:$B$48)
A20: Guardabarro trasero izquierdo | B20: 8 | C20: =B20/SUM($B$2:$B$49)
A21: Pilar trasero derecho | B21: 7 | C21: =B21/SUM($B$2:$B$50)
A22: Interior caja pick-up (Hilux) | B22: 7 | C22: =B22/SUM($B$2:$B$51)
A23: Parrilla | B23: 6 | C23: =B23/SUM($B$2:$B$52)
A24: Zócalo lateral izquierdo | B24: 6 | C24: =B24/SUM($B$2:$B$53)
A25: Optica trasera derecha | B25: 5 | C25: =B25/SUM($B$2:$B$54)
A26: Pilar delantero derecho | B26: 5 | C26: =B26/SUM($B$2:$B$55)
A27: Optica delantera derecha | B27: 5 | C27: =B27/SUM($B$2:$B$56)
A28: Espejo exterior izquierdo | B28: 4 | C28: =B28/SUM($B$2:$B$57)
A29: Pilar trasero izquierdo | B29: 4 | C29: =B29/SUM($B$2:$B$58)
A30: Estribo lateral izquierdo | B30: 4 | C30: =B30/SUM($B$2:$B$59)
A31: Optica delantera izquierda | B31: 4 | C31: =B31/SUM($B$2:$B$60)
